[2018-11-09 15:05:28,848][273332][amscache.py][line: 22][INFO] <init_cache> start....
[2018-11-09 15:05:28,910][273332][amscache.py][line: 36][INFO] <init_cache> end!
[2018-11-09 15:05:28,910][273332][orgcache.py][line: 21][INFO] <init_cache> start....
[2018-11-09 15:05:28,968][273332][orgcache.py][line: 27][INFO] <init_cache> end!
[2018-11-09 15:05:28,969][273332][locationcache.py][line: 20][INFO] <init_cache> start....
[2018-11-09 15:05:28,972][273332][locationcache.py][line: 28][INFO] <init_cache> end!
[2018-11-09 15:05:28,975][273332][mediafolder.py][line: 109][INFO] <init_folders> start...
[2018-11-09 15:05:28,976][273332][folder.py][line: 18][INFO] <init_folders> media_root: D:\dev\github\seecent\media
[2018-11-09 15:05:28,977][273332][folder.py][line: 46][INFO] <create_folder> name: D:\dev\github\seecent\media\docs
[2018-11-09 15:05:28,977][273332][folder.py][line: 46][INFO] <create_folder> name: D:\dev\github\seecent\media\images
[2018-11-09 15:05:28,979][273332][folder.py][line: 46][INFO] <create_folder> name: D:\dev\github\seecent\media\videos
[2018-11-09 15:05:28,980][273332][folder.py][line: 46][INFO] <create_folder> name: D:\dev\github\seecent\media\voices
[2018-11-09 15:05:28,980][273332][folder.py][line: 46][INFO] <create_folder> name: D:\dev\github\seecent\media\weixin
[2018-11-09 15:05:28,981][273332][folder.py][line: 46][INFO] <create_folder> name: D:\dev\github\seecent\media\weixin\images
[2018-11-09 15:05:28,981][273332][folder.py][line: 46][INFO] <create_folder> name: D:\dev\github\seecent\media\weixin\videos
[2018-11-09 15:05:28,981][273332][folder.py][line: 46][INFO] <create_folder> name: D:\dev\github\seecent\media\weixin\voices
[2018-11-09 15:05:28,981][273332][folder.py][line: 46][INFO] <create_folder> name: D:\dev\github\seecent\media\weixin\news
[2018-11-09 15:05:28,992][273332][mediafolder.py][line: 154][INFO] <init_folders> end!
[2018-11-09 15:05:52,811][279048][amscache.py][line: 22][INFO] <init_cache> start....
[2018-11-09 15:05:52,869][279048][amscache.py][line: 36][INFO] <init_cache> end!
[2018-11-09 15:05:52,870][279048][orgcache.py][line: 21][INFO] <init_cache> start....
[2018-11-09 15:05:52,925][279048][orgcache.py][line: 27][INFO] <init_cache> end!
[2018-11-09 15:05:52,925][279048][locationcache.py][line: 20][INFO] <init_cache> start....
[2018-11-09 15:05:52,932][279048][locationcache.py][line: 28][INFO] <init_cache> end!
[2018-11-09 15:05:52,935][279048][wxaccount.py][line: 131][INFO] <refresh_access_token> account_id: 1
[2018-11-09 15:05:52,943][279048][folder.py][line: 69][INFO] <create_abs_folder> name: D:\dev\github\seecent\media\weixin\weixin
[2018-11-09 15:05:52,945][279048][folder.py][line: 69][INFO] <create_abs_folder> name: D:\dev\github\seecent\media\weixin\weixin\20181109
[2018-11-09 15:05:52,948][279048][image.py][line: 56][INFO] <download> file_name: e55a6b98-e3ed-11e8-b36b-448500748e47..png, url: http://mmbiz.qpic.cn/mmbiz_png/qL1I9TcJN259J605WLynIdnoLvNAF2HERHTWibqKzWaAa6b6V3sy8HoGjRSwhYmBTPISNEkxcqylpEKVn0JrSBg/0?wx_fmt=png
[2018-11-09 15:05:53,124][279048][image.py][line: 41][ERROR] <save_image> error=
Traceback (most recent call last):
  File "D:\dev\github\seecent\cms-service\services\media\image.py", line 39, in save_image
    file_path = "{0}/{1}/{3}".format(root, path, new_file_name)
IndexError: tuple index out of range
[2018-11-09 15:05:53,133][279048][folder.py][line: 69][INFO] <create_abs_folder> name: D:\dev\github\seecent\media\weixin\weixin
[2018-11-09 15:05:53,135][279048][folder.py][line: 69][INFO] <create_abs_folder> name: D:\dev\github\seecent\media\weixin\weixin\20181109
[2018-11-09 15:05:53,136][279048][image.py][line: 56][INFO] <download> file_name: e5776070-e3ed-11e8-b185-448500748e47..jpg, url: http://mmbiz.qpic.cn/mmbiz_jpg/qL1I9TcJN259J605WLynIdnoLvNAF2HEnQODHgolBWtIYRY5iahqIyLZl08aRJo9bibFEpCNOCIkTQGjIIEacCxw/0?wx_fmt=jpeg
[2018-11-09 15:05:53,415][279048][image.py][line: 41][ERROR] <save_image> error=
Traceback (most recent call last):
  File "D:\dev\github\seecent\cms-service\services\media\image.py", line 39, in save_image
    file_path = "{0}/{1}/{3}".format(root, path, new_file_name)
IndexError: tuple index out of range
[2018-11-09 15:05:53,423][279048][folder.py][line: 69][INFO] <create_abs_folder> name: D:\dev\github\seecent\media\weixin\weixin
[2018-11-09 15:05:53,427][279048][folder.py][line: 69][INFO] <create_abs_folder> name: D:\dev\github\seecent\media\weixin\weixin\20181109
[2018-11-09 15:05:53,430][279048][image.py][line: 56][INFO] <download> file_name: e5a42be2-e3ed-11e8-a528-448500748e47..jpg, url: http://mmbiz.qpic.cn/mmbiz/qL1I9TcJN27fibQJiaIBASb63sjFicIyTXUnvYJ0wkQ2hXdBiaraDGEZG9FRuccC48PQ1LHkX4d084XphIicX71rYCQ/0?wx_fmt=jpeg
[2018-11-09 15:05:53,604][279048][image.py][line: 41][ERROR] <save_image> error=
Traceback (most recent call last):
  File "D:\dev\github\seecent\cms-service\services\media\image.py", line 39, in save_image
    file_path = "{0}/{1}/{3}".format(root, path, new_file_name)
IndexError: tuple index out of range
[2018-11-09 15:05:53,613][279048][folder.py][line: 69][INFO] <create_abs_folder> name: D:\dev\github\seecent\media\weixin\weixin
[2018-11-09 15:05:53,617][279048][folder.py][line: 69][INFO] <create_abs_folder> name: D:\dev\github\seecent\media\weixin\weixin\20181109
[2018-11-09 15:05:53,619][279048][image.py][line: 56][INFO] <download> file_name: e5c135c8-e3ed-11e8-b967-448500748e47..jpg, url: http://mmbiz.qpic.cn/mmbiz/qL1I9TcJN27fibQJiaIBASb63sjFicIyTXUnvYJ0wkQ2hXdBiaraDGEZG9FRuccC48PQ1LHkX4d084XphIicX71rYCQ/0?wx_fmt=jpeg
[2018-11-09 15:05:53,770][279048][image.py][line: 41][ERROR] <save_image> error=
Traceback (most recent call last):
  File "D:\dev\github\seecent\cms-service\services\media\image.py", line 39, in save_image
    file_path = "{0}/{1}/{3}".format(root, path, new_file_name)
IndexError: tuple index out of range
[2018-11-09 15:05:53,781][279048][folder.py][line: 69][INFO] <create_abs_folder> name: D:\dev\github\seecent\media\weixin\weixin
[2018-11-09 15:05:53,784][279048][folder.py][line: 69][INFO] <create_abs_folder> name: D:\dev\github\seecent\media\weixin\weixin\20181109
[2018-11-09 15:05:53,787][279048][image.py][line: 56][INFO] <download> file_name: e5dad0de-e3ed-11e8-8e22-448500748e47..jpg, url: http://mmbiz.qpic.cn/mmbiz/qL1I9TcJN27fibQJiaIBASb63sjFicIyTXULjyBBt4j5wTOYsvh9WsZhXLCcqaeYiaHEgaNbiatUTwOBict90zPibEBibQ/0?wx_fmt=jpeg
[2018-11-09 15:05:54,001][279048][image.py][line: 41][ERROR] <save_image> error=
Traceback (most recent call last):
  File "D:\dev\github\seecent\cms-service\services\media\image.py", line 39, in save_image
    file_path = "{0}/{1}/{3}".format(root, path, new_file_name)
IndexError: tuple index out of range
[2018-11-09 15:05:54,014][279048][folder.py][line: 69][INFO] <create_abs_folder> name: D:\dev\github\seecent\media\weixin\weixin
[2018-11-09 15:05:54,017][279048][folder.py][line: 69][INFO] <create_abs_folder> name: D:\dev\github\seecent\media\weixin\weixin\20181109
[2018-11-09 15:05:54,020][279048][image.py][line: 56][INFO] <download> file_name: e5fe5326-e3ed-11e8-834c-448500748e47..jpg, url: http://mmbiz.qpic.cn/mmbiz/qL1I9TcJN27fibQJiaIBASb63sjFicIyTXULjyBBt4j5wTOYsvh9WsZhXLCcqaeYiaHEgaNbiatUTwOBict90zPibEBibQ/0?wx_fmt=jpeg
[2018-11-09 15:05:54,209][279048][image.py][line: 41][ERROR] <save_image> error=
Traceback (most recent call last):
  File "D:\dev\github\seecent\cms-service\services\media\image.py", line 39, in save_image
    file_path = "{0}/{1}/{3}".format(root, path, new_file_name)
IndexError: tuple index out of range
[2018-11-09 15:05:54,220][279048][folder.py][line: 69][INFO] <create_abs_folder> name: D:\dev\github\seecent\media\weixin\weixin
[2018-11-09 15:05:54,223][279048][folder.py][line: 69][INFO] <create_abs_folder> name: D:\dev\github\seecent\media\weixin\weixin\20181109
[2018-11-09 15:05:54,226][279048][image.py][line: 56][INFO] <download> file_name: e61da19e-e3ed-11e8-8673-448500748e47..jpg, url: http://mmbiz.qpic.cn/mmbiz/qL1I9TcJN27fibQJiaIBASb63sjFicIyTXUK9WomZBlk0GSXgXbhTx37pIe2kmU4dSG5rGK3XBFnicAP3ed5ppictQA/0?wx_fmt=jpeg
[2018-11-09 15:05:54,401][279048][image.py][line: 41][ERROR] <save_image> error=
Traceback (most recent call last):
  File "D:\dev\github\seecent\cms-service\services\media\image.py", line 39, in save_image
    file_path = "{0}/{1}/{3}".format(root, path, new_file_name)
IndexError: tuple index out of range
[2018-11-09 15:07:57,676][278800][amscache.py][line: 22][INFO] <init_cache> start....
[2018-11-09 15:07:57,735][278800][amscache.py][line: 36][INFO] <init_cache> end!
[2018-11-09 15:07:57,735][278800][orgcache.py][line: 21][INFO] <init_cache> start....
[2018-11-09 15:07:57,793][278800][orgcache.py][line: 27][INFO] <init_cache> end!
[2018-11-09 15:07:57,793][278800][locationcache.py][line: 20][INFO] <init_cache> start....
[2018-11-09 15:07:57,796][278800][locationcache.py][line: 28][INFO] <init_cache> end!
[2018-11-09 15:07:57,799][278800][wxaccount.py][line: 131][INFO] <refresh_access_token> account_id: 1
[2018-11-09 15:07:57,804][278800][folder.py][line: 69][INFO] <create_abs_folder> name: D:\dev\github\seecent\media\weixin\images
[2018-11-09 15:07:57,804][278800][folder.py][line: 69][INFO] <create_abs_folder> name: D:\dev\github\seecent\media\weixin\images\20181109
[2018-11-09 15:07:57,805][278800][image.py][line: 56][INFO] <download> file_name: 2fc67a7a-e3ee-11e8-890c-448500748e47..png, url: http://mmbiz.qpic.cn/mmbiz_png/qL1I9TcJN259J605WLynIdnoLvNAF2HERHTWibqKzWaAa6b6V3sy8HoGjRSwhYmBTPISNEkxcqylpEKVn0JrSBg/0?wx_fmt=png
[2018-11-09 15:07:57,895][278800][folder.py][line: 69][INFO] <create_abs_folder> name: D:\dev\github\seecent\media\weixin\images
[2018-11-09 15:07:57,897][278800][folder.py][line: 69][INFO] <create_abs_folder> name: D:\dev\github\seecent\media\weixin\images\20181109
[2018-11-09 15:07:57,900][278800][image.py][line: 56][INFO] <download> file_name: 2fd4b470-e3ee-11e8-a05b-448500748e47..jpg, url: http://mmbiz.qpic.cn/mmbiz_jpg/qL1I9TcJN259J605WLynIdnoLvNAF2HEnQODHgolBWtIYRY5iahqIyLZl08aRJo9bibFEpCNOCIkTQGjIIEacCxw/0?wx_fmt=jpeg
[2018-11-09 15:07:58,172][278800][folder.py][line: 69][INFO] <create_abs_folder> name: D:\dev\github\seecent\media\weixin\images
[2018-11-09 15:07:58,174][278800][folder.py][line: 69][INFO] <create_abs_folder> name: D:\dev\github\seecent\media\weixin\images\20181109
[2018-11-09 15:07:58,177][278800][image.py][line: 56][INFO] <download> file_name: 2fff33d8-e3ee-11e8-b9c0-448500748e47..jpg, url: http://mmbiz.qpic.cn/mmbiz/qL1I9TcJN27fibQJiaIBASb63sjFicIyTXUnvYJ0wkQ2hXdBiaraDGEZG9FRuccC48PQ1LHkX4d084XphIicX71rYCQ/0?wx_fmt=jpeg
[2018-11-09 15:07:58,312][278800][folder.py][line: 69][INFO] <create_abs_folder> name: D:\dev\github\seecent\media\weixin\images
[2018-11-09 15:07:58,313][278800][folder.py][line: 69][INFO] <create_abs_folder> name: D:\dev\github\seecent\media\weixin\images\20181109
[2018-11-09 15:07:58,319][278800][image.py][line: 56][INFO] <download> file_name: 3014e21c-e3ee-11e8-a647-448500748e47..jpg, url: http://mmbiz.qpic.cn/mmbiz/qL1I9TcJN27fibQJiaIBASb63sjFicIyTXUnvYJ0wkQ2hXdBiaraDGEZG9FRuccC48PQ1LHkX4d084XphIicX71rYCQ/0?wx_fmt=jpeg
[2018-11-09 15:07:58,494][278800][folder.py][line: 69][INFO] <create_abs_folder> name: D:\dev\github\seecent\media\weixin\images
[2018-11-09 15:07:58,495][278800][folder.py][line: 69][INFO] <create_abs_folder> name: D:\dev\github\seecent\media\weixin\images\20181109
[2018-11-09 15:07:58,505][278800][image.py][line: 56][INFO] <download> file_name: 303132d0-e3ee-11e8-970c-448500748e47..jpg, url: http://mmbiz.qpic.cn/mmbiz/qL1I9TcJN27fibQJiaIBASb63sjFicIyTXULjyBBt4j5wTOYsvh9WsZhXLCcqaeYiaHEgaNbiatUTwOBict90zPibEBibQ/0?wx_fmt=jpeg
[2018-11-09 15:07:58,663][278800][folder.py][line: 69][INFO] <create_abs_folder> name: D:\dev\github\seecent\media\weixin\images
[2018-11-09 15:07:58,664][278800][folder.py][line: 69][INFO] <create_abs_folder> name: D:\dev\github\seecent\media\weixin\images\20181109
[2018-11-09 15:07:58,672][278800][image.py][line: 56][INFO] <download> file_name: 304aa79e-e3ee-11e8-bafe-448500748e47..jpg, url: http://mmbiz.qpic.cn/mmbiz/qL1I9TcJN27fibQJiaIBASb63sjFicIyTXULjyBBt4j5wTOYsvh9WsZhXLCcqaeYiaHEgaNbiatUTwOBict90zPibEBibQ/0?wx_fmt=jpeg
[2018-11-09 15:07:58,834][278800][folder.py][line: 69][INFO] <create_abs_folder> name: D:\dev\github\seecent\media\weixin\images
[2018-11-09 15:07:58,836][278800][folder.py][line: 69][INFO] <create_abs_folder> name: D:\dev\github\seecent\media\weixin\images\20181109
[2018-11-09 15:07:58,853][278800][image.py][line: 56][INFO] <download> file_name: 3066502e-e3ee-11e8-933d-448500748e47..jpg, url: http://mmbiz.qpic.cn/mmbiz/qL1I9TcJN27fibQJiaIBASb63sjFicIyTXUK9WomZBlk0GSXgXbhTx37pIe2kmU4dSG5rGK3XBFnicAP3ed5ppictQA/0?wx_fmt=jpeg
[2018-11-09 15:47:09,568][280832][amscache.py][line: 22][INFO] <init_cache> start....
[2018-11-09 15:47:09,627][280832][amscache.py][line: 36][INFO] <init_cache> end!
[2018-11-09 15:47:09,627][280832][orgcache.py][line: 21][INFO] <init_cache> start....
[2018-11-09 15:47:09,685][280832][orgcache.py][line: 27][INFO] <init_cache> end!
[2018-11-09 15:47:09,685][280832][locationcache.py][line: 20][INFO] <init_cache> start....
[2018-11-09 15:47:09,688][280832][locationcache.py][line: 28][INFO] <init_cache> end!
[2018-11-09 15:47:09,691][280832][wxaccount.py][line: 131][INFO] <refresh_access_token> account_id: 1
[2018-11-09 15:47:09,698][280832][image.py][line: 70][INFO] <create_image_folder> root: weixin, path: images
[2018-11-09 15:47:09,698][280832][image.py][line: 103][INFO] <create_abs_folder> name: D:\dev\github\seecent\media\weixin\images
[2018-11-09 15:47:09,699][280832][image.py][line: 103][INFO] <create_abs_folder> name: D:\dev\github\seecent\media\weixin\images\20181109
[2018-11-09 15:47:09,702][280832][image.py][line: 122][INFO] <download> file_name: a99d36a8-e3f3-11e8-ab96-448500748e47..png, url: http://mmbiz.qpic.cn/mmbiz_png/qL1I9TcJN259J605WLynIdnoLvNAF2HERHTWibqKzWaAa6b6V3sy8HoGjRSwhYmBTPISNEkxcqylpEKVn0JrSBg/0?wx_fmt=png
[2018-11-09 15:47:09,811][280832][image.py][line: 62][ERROR] <save_image> error=
Traceback (most recent call last):
  File "d:\miniconda3\envs\python3\lib\site-packages\sqlalchemy\engine\base.py", line 1193, in _execute_context
    context)
  File "d:\miniconda3\envs\python3\lib\site-packages\sqlalchemy\engine\default.py", line 508, in do_execute
    cursor.execute(statement, parameters)
psycopg2.ProgrammingError: can't adapt type 'module'

The above exception was the direct cause of the following exception:

Traceback (most recent call last):
  File "D:\dev\github\seecent\cms-service\services\media\image.py", line 60, in save_image
    media_file = self.db.save(files, data)
  File "D:\dev\github\seecent\cms-service\api\ext\db.py", line 610, in save
    r = self.conn.execute(table.insert(), data)
  File "d:\miniconda3\envs\python3\lib\site-packages\sqlalchemy\engine\base.py", line 948, in execute
    return meth(self, multiparams, params)
  File "d:\miniconda3\envs\python3\lib\site-packages\sqlalchemy\sql\elements.py", line 269, in _execute_on_connection
    return connection._execute_clauseelement(self, multiparams, params)
  File "d:\miniconda3\envs\python3\lib\site-packages\sqlalchemy\engine\base.py", line 1060, in _execute_clauseelement
    compiled_sql, distilled_params
  File "d:\miniconda3\envs\python3\lib\site-packages\sqlalchemy\engine\base.py", line 1200, in _execute_context
    context)
  File "d:\miniconda3\envs\python3\lib\site-packages\sqlalchemy\engine\base.py", line 1413, in _handle_dbapi_exception
    exc_info
  File "d:\miniconda3\envs\python3\lib\site-packages\sqlalchemy\util\compat.py", line 203, in raise_from_cause
    reraise(type(exception), exception, tb=exc_tb, cause=cause)
  File "d:\miniconda3\envs\python3\lib\site-packages\sqlalchemy\util\compat.py", line 186, in reraise
    raise value.with_traceback(tb)
  File "d:\miniconda3\envs\python3\lib\site-packages\sqlalchemy\engine\base.py", line 1193, in _execute_context
    context)
  File "d:\miniconda3\envs\python3\lib\site-packages\sqlalchemy\engine\default.py", line 508, in do_execute
    cursor.execute(statement, parameters)
sqlalchemy.exc.ProgrammingError: (psycopg2.ProgrammingError) can't adapt type 'module' [SQL: 'INSERT INTO cms_files (uuid, name, original_filename, file_path, type, folder_id, is_public, created_date) VALUES (%(uuid)s, %(name)s, %(original_filename)s, %(file_path)s, %(type)s, %(folder_id)s, %(is_public)s, %(created_date)s) RETURNING cms_files.id'] [parameters: {'uuid': <module 'uuid' from 'd:\\miniconda3\\envs\\python3\\lib\\uuid.py'>, 'name': 'a99d36a8-e3f3-11e8-ab96-448500748e47..png', 'original_filename': '1490070426805600.png', 'file_path': 'weixin/images/a99d36a8-e3f3-11e8-ab96-448500748e47..png', 'type': 'IMAGE', 'folder_id': 7, 'is_public': 0, 'created_date': datetime.datetime(2018, 11, 9, 15, 47, 9, 810529)}] (Background on this error at: http://sqlalche.me/e/f405)
[2018-11-09 15:47:09,824][280832][image.py][line: 122][INFO] <download> file_name: a9b00e24-e3f3-11e8-aee3-448500748e47..jpg, url: http://mmbiz.qpic.cn/mmbiz_jpg/qL1I9TcJN259J605WLynIdnoLvNAF2HEnQODHgolBWtIYRY5iahqIyLZl08aRJo9bibFEpCNOCIkTQGjIIEacCxw/0?wx_fmt=jpeg
[2018-11-09 15:47:10,076][280832][image.py][line: 62][ERROR] <save_image> error=
Traceback (most recent call last):
  File "d:\miniconda3\envs\python3\lib\site-packages\sqlalchemy\engine\base.py", line 1193, in _execute_context
    context)
  File "d:\miniconda3\envs\python3\lib\site-packages\sqlalchemy\engine\default.py", line 508, in do_execute
    cursor.execute(statement, parameters)
psycopg2.ProgrammingError: can't adapt type 'module'

The above exception was the direct cause of the following exception:

Traceback (most recent call last):
  File "D:\dev\github\seecent\cms-service\services\media\image.py", line 60, in save_image
    media_file = self.db.save(files, data)
  File "D:\dev\github\seecent\cms-service\api\ext\db.py", line 610, in save
    r = self.conn.execute(table.insert(), data)
  File "d:\miniconda3\envs\python3\lib\site-packages\sqlalchemy\engine\base.py", line 948, in execute
    return meth(self, multiparams, params)
  File "d:\miniconda3\envs\python3\lib\site-packages\sqlalchemy\sql\elements.py", line 269, in _execute_on_connection
    return connection._execute_clauseelement(self, multiparams, params)
  File "d:\miniconda3\envs\python3\lib\site-packages\sqlalchemy\engine\base.py", line 1060, in _execute_clauseelement
    compiled_sql, distilled_params
  File "d:\miniconda3\envs\python3\lib\site-packages\sqlalchemy\engine\base.py", line 1200, in _execute_context
    context)
  File "d:\miniconda3\envs\python3\lib\site-packages\sqlalchemy\engine\base.py", line 1413, in _handle_dbapi_exception
    exc_info
  File "d:\miniconda3\envs\python3\lib\site-packages\sqlalchemy\util\compat.py", line 203, in raise_from_cause
    reraise(type(exception), exception, tb=exc_tb, cause=cause)
  File "d:\miniconda3\envs\python3\lib\site-packages\sqlalchemy\util\compat.py", line 186, in reraise
    raise value.with_traceback(tb)
  File "d:\miniconda3\envs\python3\lib\site-packages\sqlalchemy\engine\base.py", line 1193, in _execute_context
    context)
  File "d:\miniconda3\envs\python3\lib\site-packages\sqlalchemy\engine\default.py", line 508, in do_execute
    cursor.execute(statement, parameters)
sqlalchemy.exc.ProgrammingError: (psycopg2.ProgrammingError) can't adapt type 'module' [SQL: 'INSERT INTO cms_files (uuid, name, original_filename, file_path, type, folder_id, is_public, created_date) VALUES (%(uuid)s, %(name)s, %(original_filename)s, %(file_path)s, %(type)s, %(folder_id)s, %(is_public)s, %(created_date)s) RETURNING cms_files.id'] [parameters: {'uuid': <module 'uuid' from 'd:\\miniconda3\\envs\\python3\\lib\\uuid.py'>, 'name': 'a9b00e24-e3f3-11e8-aee3-448500748e47..jpg', 'original_filename': '14900695891309444.jpg', 'file_path': 'weixin/images/a9b00e24-e3f3-11e8-aee3-448500748e47..jpg', 'type': 'IMAGE', 'folder_id': 7, 'is_public': 0, 'created_date': datetime.datetime(2018, 11, 9, 15, 47, 10, 74677)}] (Background on this error at: http://sqlalche.me/e/f405)
[2018-11-09 15:47:10,092][280832][image.py][line: 122][INFO] <download> file_name: a9d8f928-e3f3-11e8-bab2-448500748e47..jpg, url: http://mmbiz.qpic.cn/mmbiz/qL1I9TcJN27fibQJiaIBASb63sjFicIyTXUnvYJ0wkQ2hXdBiaraDGEZG9FRuccC48PQ1LHkX4d084XphIicX71rYCQ/0?wx_fmt=jpeg
[2018-11-09 15:47:10,256][280832][image.py][line: 62][ERROR] <save_image> error=
Traceback (most recent call last):
  File "d:\miniconda3\envs\python3\lib\site-packages\sqlalchemy\engine\base.py", line 1193, in _execute_context
    context)
  File "d:\miniconda3\envs\python3\lib\site-packages\sqlalchemy\engine\default.py", line 508, in do_execute
    cursor.execute(statement, parameters)
psycopg2.ProgrammingError: can't adapt type 'module'

The above exception was the direct cause of the following exception:

Traceback (most recent call last):
  File "D:\dev\github\seecent\cms-service\services\media\image.py", line 60, in save_image
    media_file = self.db.save(files, data)
  File "D:\dev\github\seecent\cms-service\api\ext\db.py", line 610, in save
    r = self.conn.execute(table.insert(), data)
  File "d:\miniconda3\envs\python3\lib\site-packages\sqlalchemy\engine\base.py", line 948, in execute
    return meth(self, multiparams, params)
  File "d:\miniconda3\envs\python3\lib\site-packages\sqlalchemy\sql\elements.py", line 269, in _execute_on_connection
    return connection._execute_clauseelement(self, multiparams, params)
  File "d:\miniconda3\envs\python3\lib\site-packages\sqlalchemy\engine\base.py", line 1060, in _execute_clauseelement
    compiled_sql, distilled_params
  File "d:\miniconda3\envs\python3\lib\site-packages\sqlalchemy\engine\base.py", line 1200, in _execute_context
    context)
  File "d:\miniconda3\envs\python3\lib\site-packages\sqlalchemy\engine\base.py", line 1413, in _handle_dbapi_exception
    exc_info
  File "d:\miniconda3\envs\python3\lib\site-packages\sqlalchemy\util\compat.py", line 203, in raise_from_cause
    reraise(type(exception), exception, tb=exc_tb, cause=cause)
  File "d:\miniconda3\envs\python3\lib\site-packages\sqlalchemy\util\compat.py", line 186, in reraise
    raise value.with_traceback(tb)
  File "d:\miniconda3\envs\python3\lib\site-packages\sqlalchemy\engine\base.py", line 1193, in _execute_context
    context)
  File "d:\miniconda3\envs\python3\lib\site-packages\sqlalchemy\engine\default.py", line 508, in do_execute
    cursor.execute(statement, parameters)
sqlalchemy.exc.ProgrammingError: (psycopg2.ProgrammingError) can't adapt type 'module' [SQL: 'INSERT INTO cms_files (uuid, name, original_filename, file_path, type, folder_id, is_public, created_date) VALUES (%(uuid)s, %(name)s, %(original_filename)s, %(file_path)s, %(type)s, %(folder_id)s, %(is_public)s, %(created_date)s) RETURNING cms_files.id'] [parameters: {'uuid': <module 'uuid' from 'd:\\miniconda3\\envs\\python3\\lib\\uuid.py'>, 'name': 'a9d8f928-e3f3-11e8-bab2-448500748e47..jpg', 'original_filename': 'promotion.jpg', 'file_path': 'weixin/images/a9d8f928-e3f3-11e8-bab2-448500748e47..jpg', 'type': 'IMAGE', 'folder_id': 7, 'is_public': 0, 'created_date': datetime.datetime(2018, 11, 9, 15, 47, 10, 255628)}] (Background on this error at: http://sqlalche.me/e/f405)
[2018-11-09 15:47:10,275][280832][image.py][line: 122][INFO] <download> file_name: a9f4e26e-e3f3-11e8-9302-448500748e47..jpg, url: http://mmbiz.qpic.cn/mmbiz/qL1I9TcJN27fibQJiaIBASb63sjFicIyTXUnvYJ0wkQ2hXdBiaraDGEZG9FRuccC48PQ1LHkX4d084XphIicX71rYCQ/0?wx_fmt=jpeg
[2018-11-09 15:47:10,461][280832][image.py][line: 62][ERROR] <save_image> error=
Traceback (most recent call last):
  File "d:\miniconda3\envs\python3\lib\site-packages\sqlalchemy\engine\base.py", line 1193, in _execute_context
    context)
  File "d:\miniconda3\envs\python3\lib\site-packages\sqlalchemy\engine\default.py", line 508, in do_execute
    cursor.execute(statement, parameters)
psycopg2.ProgrammingError: can't adapt type 'module'

The above exception was the direct cause of the following exception:

Traceback (most recent call last):
  File "D:\dev\github\seecent\cms-service\services\media\image.py", line 60, in save_image
    media_file = self.db.save(files, data)
  File "D:\dev\github\seecent\cms-service\api\ext\db.py", line 610, in save
    r = self.conn.execute(table.insert(), data)
  File "d:\miniconda3\envs\python3\lib\site-packages\sqlalchemy\engine\base.py", line 948, in execute
    return meth(self, multiparams, params)
  File "d:\miniconda3\envs\python3\lib\site-packages\sqlalchemy\sql\elements.py", line 269, in _execute_on_connection
    return connection._execute_clauseelement(self, multiparams, params)
  File "d:\miniconda3\envs\python3\lib\site-packages\sqlalchemy\engine\base.py", line 1060, in _execute_clauseelement
    compiled_sql, distilled_params
  File "d:\miniconda3\envs\python3\lib\site-packages\sqlalchemy\engine\base.py", line 1200, in _execute_context
    context)
  File "d:\miniconda3\envs\python3\lib\site-packages\sqlalchemy\engine\base.py", line 1413, in _handle_dbapi_exception
    exc_info
  File "d:\miniconda3\envs\python3\lib\site-packages\sqlalchemy\util\compat.py", line 203, in raise_from_cause
    reraise(type(exception), exception, tb=exc_tb, cause=cause)
  File "d:\miniconda3\envs\python3\lib\site-packages\sqlalchemy\util\compat.py", line 186, in reraise
    raise value.with_traceback(tb)
  File "d:\miniconda3\envs\python3\lib\site-packages\sqlalchemy\engine\base.py", line 1193, in _execute_context
    context)
  File "d:\miniconda3\envs\python3\lib\site-packages\sqlalchemy\engine\default.py", line 508, in do_execute
    cursor.execute(statement, parameters)
sqlalchemy.exc.ProgrammingError: (psycopg2.ProgrammingError) can't adapt type 'module' [SQL: 'INSERT INTO cms_files (uuid, name, original_filename, file_path, type, folder_id, is_public, created_date) VALUES (%(uuid)s, %(name)s, %(original_filename)s, %(file_path)s, %(type)s, %(folder_id)s, %(is_public)s, %(created_date)s) RETURNING cms_files.id'] [parameters: {'uuid': <module 'uuid' from 'd:\\miniconda3\\envs\\python3\\lib\\uuid.py'>, 'name': 'a9f4e26e-e3f3-11e8-9302-448500748e47..jpg', 'original_filename': 'promotion.jpg', 'file_path': 'weixin/images/a9f4e26e-e3f3-11e8-9302-448500748e47..jpg', 'type': 'IMAGE', 'folder_id': 7, 'is_public': 0, 'created_date': datetime.datetime(2018, 11, 9, 15, 47, 10, 460851)}] (Background on this error at: http://sqlalche.me/e/f405)
[2018-11-09 15:47:10,480][280832][image.py][line: 122][INFO] <download> file_name: aa143414-e3f3-11e8-9fd2-448500748e47..jpg, url: http://mmbiz.qpic.cn/mmbiz/qL1I9TcJN27fibQJiaIBASb63sjFicIyTXULjyBBt4j5wTOYsvh9WsZhXLCcqaeYiaHEgaNbiatUTwOBict90zPibEBibQ/0?wx_fmt=jpeg
[2018-11-09 15:47:10,643][280832][image.py][line: 62][ERROR] <save_image> error=
Traceback (most recent call last):
  File "d:\miniconda3\envs\python3\lib\site-packages\sqlalchemy\engine\base.py", line 1193, in _execute_context
    context)
  File "d:\miniconda3\envs\python3\lib\site-packages\sqlalchemy\engine\default.py", line 508, in do_execute
    cursor.execute(statement, parameters)
psycopg2.ProgrammingError: can't adapt type 'module'

The above exception was the direct cause of the following exception:

Traceback (most recent call last):
  File "D:\dev\github\seecent\cms-service\services\media\image.py", line 60, in save_image
    media_file = self.db.save(files, data)
  File "D:\dev\github\seecent\cms-service\api\ext\db.py", line 610, in save
    r = self.conn.execute(table.insert(), data)
  File "d:\miniconda3\envs\python3\lib\site-packages\sqlalchemy\engine\base.py", line 948, in execute
    return meth(self, multiparams, params)
  File "d:\miniconda3\envs\python3\lib\site-packages\sqlalchemy\sql\elements.py", line 269, in _execute_on_connection
    return connection._execute_clauseelement(self, multiparams, params)
  File "d:\miniconda3\envs\python3\lib\site-packages\sqlalchemy\engine\base.py", line 1060, in _execute_clauseelement
    compiled_sql, distilled_params
  File "d:\miniconda3\envs\python3\lib\site-packages\sqlalchemy\engine\base.py", line 1200, in _execute_context
    context)
  File "d:\miniconda3\envs\python3\lib\site-packages\sqlalchemy\engine\base.py", line 1413, in _handle_dbapi_exception
    exc_info
  File "d:\miniconda3\envs\python3\lib\site-packages\sqlalchemy\util\compat.py", line 203, in raise_from_cause
    reraise(type(exception), exception, tb=exc_tb, cause=cause)
  File "d:\miniconda3\envs\python3\lib\site-packages\sqlalchemy\util\compat.py", line 186, in reraise
    raise value.with_traceback(tb)
  File "d:\miniconda3\envs\python3\lib\site-packages\sqlalchemy\engine\base.py", line 1193, in _execute_context
    context)
  File "d:\miniconda3\envs\python3\lib\site-packages\sqlalchemy\engine\default.py", line 508, in do_execute
    cursor.execute(statement, parameters)
sqlalchemy.exc.ProgrammingError: (psycopg2.ProgrammingError) can't adapt type 'module' [SQL: 'INSERT INTO cms_files (uuid, name, original_filename, file_path, type, folder_id, is_public, created_date) VALUES (%(uuid)s, %(name)s, %(original_filename)s, %(file_path)s, %(type)s, %(folder_id)s, %(is_public)s, %(created_date)s) RETURNING cms_files.id'] [parameters: {'uuid': <module 'uuid' from 'd:\\miniconda3\\envs\\python3\\lib\\uuid.py'>, 'name': 'aa143414-e3f3-11e8-9fd2-448500748e47..jpg', 'original_filename': 'promotion.jpg', 'file_path': 'weixin/images/aa143414-e3f3-11e8-9fd2-448500748e47..jpg', 'type': 'IMAGE', 'folder_id': 7, 'is_public': 0, 'created_date': datetime.datetime(2018, 11, 9, 15, 47, 10, 642970)}] (Background on this error at: http://sqlalche.me/e/f405)
[2018-11-09 15:47:10,656][280832][image.py][line: 122][INFO] <download> file_name: aa2eec28-e3f3-11e8-bc89-448500748e47..jpg, url: http://mmbiz.qpic.cn/mmbiz/qL1I9TcJN27fibQJiaIBASb63sjFicIyTXULjyBBt4j5wTOYsvh9WsZhXLCcqaeYiaHEgaNbiatUTwOBict90zPibEBibQ/0?wx_fmt=jpeg
[2018-11-09 15:47:10,832][280832][image.py][line: 62][ERROR] <save_image> error=
Traceback (most recent call last):
  File "d:\miniconda3\envs\python3\lib\site-packages\sqlalchemy\engine\base.py", line 1193, in _execute_context
    context)
  File "d:\miniconda3\envs\python3\lib\site-packages\sqlalchemy\engine\default.py", line 508, in do_execute
    cursor.execute(statement, parameters)
psycopg2.ProgrammingError: can't adapt type 'module'

The above exception was the direct cause of the following exception:

Traceback (most recent call last):
  File "D:\dev\github\seecent\cms-service\services\media\image.py", line 60, in save_image
    media_file = self.db.save(files, data)
  File "D:\dev\github\seecent\cms-service\api\ext\db.py", line 610, in save
    r = self.conn.execute(table.insert(), data)
  File "d:\miniconda3\envs\python3\lib\site-packages\sqlalchemy\engine\base.py", line 948, in execute
    return meth(self, multiparams, params)
  File "d:\miniconda3\envs\python3\lib\site-packages\sqlalchemy\sql\elements.py", line 269, in _execute_on_connection
    return connection._execute_clauseelement(self, multiparams, params)
  File "d:\miniconda3\envs\python3\lib\site-packages\sqlalchemy\engine\base.py", line 1060, in _execute_clauseelement
    compiled_sql, distilled_params
  File "d:\miniconda3\envs\python3\lib\site-packages\sqlalchemy\engine\base.py", line 1200, in _execute_context
    context)
  File "d:\miniconda3\envs\python3\lib\site-packages\sqlalchemy\engine\base.py", line 1413, in _handle_dbapi_exception
    exc_info
  File "d:\miniconda3\envs\python3\lib\site-packages\sqlalchemy\util\compat.py", line 203, in raise_from_cause
    reraise(type(exception), exception, tb=exc_tb, cause=cause)
  File "d:\miniconda3\envs\python3\lib\site-packages\sqlalchemy\util\compat.py", line 186, in reraise
    raise value.with_traceback(tb)
  File "d:\miniconda3\envs\python3\lib\site-packages\sqlalchemy\engine\base.py", line 1193, in _execute_context
    context)
  File "d:\miniconda3\envs\python3\lib\site-packages\sqlalchemy\engine\default.py", line 508, in do_execute
    cursor.execute(statement, parameters)
sqlalchemy.exc.ProgrammingError: (psycopg2.ProgrammingError) can't adapt type 'module' [SQL: 'INSERT INTO cms_files (uuid, name, original_filename, file_path, type, folder_id, is_public, created_date) VALUES (%(uuid)s, %(name)s, %(original_filename)s, %(file_path)s, %(type)s, %(folder_id)s, %(is_public)s, %(created_date)s) RETURNING cms_files.id'] [parameters: {'uuid': <module 'uuid' from 'd:\\miniconda3\\envs\\python3\\lib\\uuid.py'>, 'name': 'aa2eec28-e3f3-11e8-bc89-448500748e47..jpg', 'original_filename': 'promotion.jpg', 'file_path': 'weixin/images/aa2eec28-e3f3-11e8-bc89-448500748e47..jpg', 'type': 'IMAGE', 'folder_id': 7, 'is_public': 0, 'created_date': datetime.datetime(2018, 11, 9, 15, 47, 10, 831571)}] (Background on this error at: http://sqlalche.me/e/f405)
[2018-11-09 15:47:10,833][280832][image.py][line: 122][INFO] <download> file_name: aa4a045e-e3f3-11e8-a496-448500748e47..jpg, url: http://mmbiz.qpic.cn/mmbiz/qL1I9TcJN27fibQJiaIBASb63sjFicIyTXUK9WomZBlk0GSXgXbhTx37pIe2kmU4dSG5rGK3XBFnicAP3ed5ppictQA/0?wx_fmt=jpeg
[2018-11-09 15:47:10,980][280832][image.py][line: 62][ERROR] <save_image> error=
Traceback (most recent call last):
  File "d:\miniconda3\envs\python3\lib\site-packages\sqlalchemy\engine\base.py", line 1193, in _execute_context
    context)
  File "d:\miniconda3\envs\python3\lib\site-packages\sqlalchemy\engine\default.py", line 508, in do_execute
    cursor.execute(statement, parameters)
psycopg2.ProgrammingError: can't adapt type 'module'

The above exception was the direct cause of the following exception:

Traceback (most recent call last):
  File "D:\dev\github\seecent\cms-service\services\media\image.py", line 60, in save_image
    media_file = self.db.save(files, data)
  File "D:\dev\github\seecent\cms-service\api\ext\db.py", line 610, in save
    r = self.conn.execute(table.insert(), data)
  File "d:\miniconda3\envs\python3\lib\site-packages\sqlalchemy\engine\base.py", line 948, in execute
    return meth(self, multiparams, params)
  File "d:\miniconda3\envs\python3\lib\site-packages\sqlalchemy\sql\elements.py", line 269, in _execute_on_connection
    return connection._execute_clauseelement(self, multiparams, params)
  File "d:\miniconda3\envs\python3\lib\site-packages\sqlalchemy\engine\base.py", line 1060, in _execute_clauseelement
    compiled_sql, distilled_params
  File "d:\miniconda3\envs\python3\lib\site-packages\sqlalchemy\engine\base.py", line 1200, in _execute_context
    context)
  File "d:\miniconda3\envs\python3\lib\site-packages\sqlalchemy\engine\base.py", line 1413, in _handle_dbapi_exception
    exc_info
  File "d:\miniconda3\envs\python3\lib\site-packages\sqlalchemy\util\compat.py", line 203, in raise_from_cause
    reraise(type(exception), exception, tb=exc_tb, cause=cause)
  File "d:\miniconda3\envs\python3\lib\site-packages\sqlalchemy\util\compat.py", line 186, in reraise
    raise value.with_traceback(tb)
  File "d:\miniconda3\envs\python3\lib\site-packages\sqlalchemy\engine\base.py", line 1193, in _execute_context
    context)
  File "d:\miniconda3\envs\python3\lib\site-packages\sqlalchemy\engine\default.py", line 508, in do_execute
    cursor.execute(statement, parameters)
sqlalchemy.exc.ProgrammingError: (psycopg2.ProgrammingError) can't adapt type 'module' [SQL: 'INSERT INTO cms_files (uuid, name, original_filename, file_path, type, folder_id, is_public, created_date) VALUES (%(uuid)s, %(name)s, %(original_filename)s, %(file_path)s, %(type)s, %(folder_id)s, %(is_public)s, %(created_date)s) RETURNING cms_files.id'] [parameters: {'uuid': <module 'uuid' from 'd:\\miniconda3\\envs\\python3\\lib\\uuid.py'>, 'name': 'aa4a045e-e3f3-11e8-a496-448500748e47..jpg', 'original_filename': 'bg.jpg', 'file_path': 'weixin/images/aa4a045e-e3f3-11e8-a496-448500748e47..jpg', 'type': 'IMAGE', 'folder_id': 7, 'is_public': 0, 'created_date': datetime.datetime(2018, 11, 9, 15, 47, 10, 978477)}] (Background on this error at: http://sqlalche.me/e/f405)
[2018-11-09 15:47:55,396][281304][amscache.py][line: 22][INFO] <init_cache> start....
[2018-11-09 15:47:55,453][281304][amscache.py][line: 36][INFO] <init_cache> end!
[2018-11-09 15:47:55,453][281304][orgcache.py][line: 21][INFO] <init_cache> start....
[2018-11-09 15:47:55,512][281304][orgcache.py][line: 27][INFO] <init_cache> end!
[2018-11-09 15:47:55,512][281304][locationcache.py][line: 20][INFO] <init_cache> start....
[2018-11-09 15:47:55,514][281304][locationcache.py][line: 28][INFO] <init_cache> end!
[2018-11-09 15:47:55,517][281304][wxaccount.py][line: 131][INFO] <refresh_access_token> account_id: 1
[2018-11-09 15:47:55,523][281304][image.py][line: 70][INFO] <create_image_folder> root: weixin, path: images
[2018-11-09 15:47:55,524][281304][image.py][line: 103][INFO] <create_abs_folder> name: D:\dev\github\seecent\media\weixin\images
[2018-11-09 15:47:55,524][281304][image.py][line: 103][INFO] <create_abs_folder> name: D:\dev\github\seecent\media\weixin\images\20181109
[2018-11-09 15:47:55,527][281304][image.py][line: 122][INFO] <download> file_name: c4edb62e-e3f3-11e8-860a-448500748e47..png, url: http://mmbiz.qpic.cn/mmbiz_png/qL1I9TcJN259J605WLynIdnoLvNAF2HERHTWibqKzWaAa6b6V3sy8HoGjRSwhYmBTPISNEkxcqylpEKVn0JrSBg/0?wx_fmt=png
[2018-11-09 15:47:55,614][281304][image.py][line: 122][INFO] <download> file_name: c4fafd0a-e3f3-11e8-a466-448500748e47..jpg, url: http://mmbiz.qpic.cn/mmbiz_jpg/qL1I9TcJN259J605WLynIdnoLvNAF2HEnQODHgolBWtIYRY5iahqIyLZl08aRJo9bibFEpCNOCIkTQGjIIEacCxw/0?wx_fmt=jpeg
[2018-11-09 15:47:55,885][281304][image.py][line: 122][INFO] <download> file_name: c5246b06-e3f3-11e8-b8f7-448500748e47..jpg, url: http://mmbiz.qpic.cn/mmbiz/qL1I9TcJN27fibQJiaIBASb63sjFicIyTXUnvYJ0wkQ2hXdBiaraDGEZG9FRuccC48PQ1LHkX4d084XphIicX71rYCQ/0?wx_fmt=jpeg
[2018-11-09 15:47:56,052][281304][image.py][line: 122][INFO] <download> file_name: c53df224-e3f3-11e8-bbae-448500748e47..jpg, url: http://mmbiz.qpic.cn/mmbiz/qL1I9TcJN27fibQJiaIBASb63sjFicIyTXUnvYJ0wkQ2hXdBiaraDGEZG9FRuccC48PQ1LHkX4d084XphIicX71rYCQ/0?wx_fmt=jpeg
[2018-11-09 15:47:56,210][281304][image.py][line: 122][INFO] <download> file_name: c555ceb4-e3f3-11e8-8fc2-448500748e47..jpg, url: http://mmbiz.qpic.cn/mmbiz/qL1I9TcJN27fibQJiaIBASb63sjFicIyTXULjyBBt4j5wTOYsvh9WsZhXLCcqaeYiaHEgaNbiatUTwOBict90zPibEBibQ/0?wx_fmt=jpeg
[2018-11-09 15:47:56,406][281304][image.py][line: 122][INFO] <download> file_name: c573f078-e3f3-11e8-8863-448500748e47..jpg, url: http://mmbiz.qpic.cn/mmbiz/qL1I9TcJN27fibQJiaIBASb63sjFicIyTXULjyBBt4j5wTOYsvh9WsZhXLCcqaeYiaHEgaNbiatUTwOBict90zPibEBibQ/0?wx_fmt=jpeg
[2018-11-09 15:47:56,550][281304][image.py][line: 122][INFO] <download> file_name: c589d4ec-e3f3-11e8-a4d1-448500748e47..jpg, url: http://mmbiz.qpic.cn/mmbiz/qL1I9TcJN27fibQJiaIBASb63sjFicIyTXUK9WomZBlk0GSXgXbhTx37pIe2kmU4dSG5rGK3XBFnicAP3ed5ppictQA/0?wx_fmt=jpeg
[2018-11-09 15:52:36,442][281240][amscache.py][line: 22][INFO] <init_cache> start....
[2018-11-09 15:52:36,500][281240][amscache.py][line: 36][INFO] <init_cache> end!
[2018-11-09 15:52:36,500][281240][orgcache.py][line: 21][INFO] <init_cache> start....
[2018-11-09 15:52:36,555][281240][orgcache.py][line: 27][INFO] <init_cache> end!
[2018-11-09 15:52:36,556][281240][locationcache.py][line: 20][INFO] <init_cache> start....
[2018-11-09 15:52:36,558][281240][locationcache.py][line: 28][INFO] <init_cache> end!
[2018-11-09 15:52:36,561][281240][wxaccount.py][line: 131][INFO] <refresh_access_token> account_id: 1
[2018-11-09 15:52:36,567][281240][image.py][line: 72][INFO] <create_image_folder> root: weixin, path: images
[2018-11-09 15:52:36,567][281240][image.py][line: 108][INFO] <create_abs_folder> name: D:\dev\github\seecent\media\weixin\images
[2018-11-09 15:52:36,567][281240][image.py][line: 108][INFO] <create_abs_folder> name: D:\dev\github\seecent\media\weixin\images\20181109
[2018-11-09 15:52:36,569][281240][image.py][line: 64][ERROR] <save_image> error=
Traceback (most recent call last):
  File "D:\dev\github\seecent\cms-service\services\media\image.py", line 49, in save_image
    ', file_name: ' + file_name)
TypeError: must be str, not int
[2018-11-09 15:52:36,570][281240][image.py][line: 64][ERROR] <save_image> error=
Traceback (most recent call last):
  File "D:\dev\github\seecent\cms-service\services\media\image.py", line 49, in save_image
    ', file_name: ' + file_name)
TypeError: must be str, not int
[2018-11-09 15:52:36,570][281240][image.py][line: 64][ERROR] <save_image> error=
Traceback (most recent call last):
  File "D:\dev\github\seecent\cms-service\services\media\image.py", line 49, in save_image
    ', file_name: ' + file_name)
TypeError: must be str, not int
[2018-11-09 15:52:36,571][281240][image.py][line: 64][ERROR] <save_image> error=
Traceback (most recent call last):
  File "D:\dev\github\seecent\cms-service\services\media\image.py", line 49, in save_image
    ', file_name: ' + file_name)
TypeError: must be str, not int
[2018-11-09 15:52:36,572][281240][image.py][line: 64][ERROR] <save_image> error=
Traceback (most recent call last):
  File "D:\dev\github\seecent\cms-service\services\media\image.py", line 49, in save_image
    ', file_name: ' + file_name)
TypeError: must be str, not int
[2018-11-09 15:52:36,573][281240][image.py][line: 64][ERROR] <save_image> error=
Traceback (most recent call last):
  File "D:\dev\github\seecent\cms-service\services\media\image.py", line 49, in save_image
    ', file_name: ' + file_name)
TypeError: must be str, not int
[2018-11-09 15:52:36,575][281240][image.py][line: 64][ERROR] <save_image> error=
Traceback (most recent call last):
  File "D:\dev\github\seecent\cms-service\services\media\image.py", line 49, in save_image
    ', file_name: ' + file_name)
TypeError: must be str, not int
[2018-11-09 15:53:26,755][276368][amscache.py][line: 22][INFO] <init_cache> start....
[2018-11-09 15:53:26,812][276368][amscache.py][line: 36][INFO] <init_cache> end!
[2018-11-09 15:53:26,812][276368][orgcache.py][line: 21][INFO] <init_cache> start....
[2018-11-09 15:53:26,869][276368][orgcache.py][line: 27][INFO] <init_cache> end!
[2018-11-09 15:53:26,869][276368][locationcache.py][line: 20][INFO] <init_cache> start....
[2018-11-09 15:53:26,872][276368][locationcache.py][line: 28][INFO] <init_cache> end!
[2018-11-09 15:53:26,875][276368][wxaccount.py][line: 131][INFO] <refresh_access_token> account_id: 1
[2018-11-09 15:53:26,881][276368][image.py][line: 72][INFO] <create_image_folder> root: weixin, path: images
[2018-11-09 15:53:26,881][276368][image.py][line: 108][INFO] <create_abs_folder> name: D:\dev\github\seecent\media\weixin\images
[2018-11-09 15:53:26,882][276368][image.py][line: 108][INFO] <create_abs_folder> name: D:\dev\github\seecent\media\weixin\images\20181109
[2018-11-09 15:53:26,884][276368][image.py][line: 49][INFO] <save_image> folder_id: 7, file_name: 1490070426805600.png
[2018-11-09 15:53:26,885][276368][image.py][line: 127][INFO] <download> file_name: 8a6f005c-e3f4-11e8-aebf-448500748e47.png, url: http://mmbiz.qpic.cn/mmbiz_png/qL1I9TcJN259J605WLynIdnoLvNAF2HERHTWibqKzWaAa6b6V3sy8HoGjRSwhYmBTPISNEkxcqylpEKVn0JrSBg/0?wx_fmt=png
[2018-11-09 15:53:26,994][276368][image.py][line: 49][INFO] <save_image> folder_id: 7, file_name: 14900695891309444.jpg
[2018-11-09 15:53:26,995][276368][image.py][line: 127][INFO] <download> file_name: 8a7fc79e-e3f4-11e8-aa40-448500748e47.jpg, url: http://mmbiz.qpic.cn/mmbiz_jpg/qL1I9TcJN259J605WLynIdnoLvNAF2HEnQODHgolBWtIYRY5iahqIyLZl08aRJo9bibFEpCNOCIkTQGjIIEacCxw/0?wx_fmt=jpeg
[2018-11-09 15:53:27,303][276368][image.py][line: 49][INFO] <save_image> folder_id: 7, file_name: promotion.jpg
[2018-11-09 15:53:27,304][276368][image.py][line: 127][INFO] <download> file_name: 8aaeefa6-e3f4-11e8-a8f1-448500748e47.jpg, url: http://mmbiz.qpic.cn/mmbiz/qL1I9TcJN27fibQJiaIBASb63sjFicIyTXUnvYJ0wkQ2hXdBiaraDGEZG9FRuccC48PQ1LHkX4d084XphIicX71rYCQ/0?wx_fmt=jpeg
[2018-11-09 15:53:27,456][276368][image.py][line: 49][INFO] <save_image> folder_id: 7, file_name: promotion.jpg
[2018-11-09 15:53:27,457][276368][image.py][line: 127][INFO] <download> file_name: 8ac6139e-e3f4-11e8-97ea-448500748e47.jpg, url: http://mmbiz.qpic.cn/mmbiz/qL1I9TcJN27fibQJiaIBASb63sjFicIyTXUnvYJ0wkQ2hXdBiaraDGEZG9FRuccC48PQ1LHkX4d084XphIicX71rYCQ/0?wx_fmt=jpeg
[2018-11-09 15:53:27,644][276368][image.py][line: 49][INFO] <save_image> folder_id: 7, file_name: promotion.jpg
[2018-11-09 15:53:27,645][276368][image.py][line: 127][INFO] <download> file_name: 8ae2e69e-e3f4-11e8-8928-448500748e47.jpg, url: http://mmbiz.qpic.cn/mmbiz/qL1I9TcJN27fibQJiaIBASb63sjFicIyTXULjyBBt4j5wTOYsvh9WsZhXLCcqaeYiaHEgaNbiatUTwOBict90zPibEBibQ/0?wx_fmt=jpeg
[2018-11-09 15:53:27,830][276368][image.py][line: 49][INFO] <save_image> folder_id: 7, file_name: promotion.jpg
[2018-11-09 15:53:27,830][276368][image.py][line: 127][INFO] <download> file_name: 8aff1c14-e3f4-11e8-b013-448500748e47.jpg, url: http://mmbiz.qpic.cn/mmbiz/qL1I9TcJN27fibQJiaIBASb63sjFicIyTXULjyBBt4j5wTOYsvh9WsZhXLCcqaeYiaHEgaNbiatUTwOBict90zPibEBibQ/0?wx_fmt=jpeg
[2018-11-09 15:53:27,993][276368][image.py][line: 49][INFO] <save_image> folder_id: 7, file_name: bg.jpg
[2018-11-09 15:53:27,994][276368][image.py][line: 127][INFO] <download> file_name: 8b182a28-e3f4-11e8-93a7-448500748e47.jpg, url: http://mmbiz.qpic.cn/mmbiz/qL1I9TcJN27fibQJiaIBASb63sjFicIyTXUK9WomZBlk0GSXgXbhTx37pIe2kmU4dSG5rGK3XBFnicAP3ed5ppictQA/0?wx_fmt=jpeg
